# 47장 에러처리

# 47.1 에러 처리의 필요성

- 에러가 발생하지 않는 코드를 작성하는 것은 불가능하다. 에러는 언제나 발생할 수 있다. 하지만 에러에 대처하지 않고 방치하면 프로그램은 강제 종료된다.
- try…catch 문을 사용해 에러에 적절하게 대응하면 프로그램이 강제 종료되지 않고 계속해서 코드를 실행시킬 수 있다.

```jsx
try {
	foo();
}catch (error){
	console.error('[에러 발생]', error);
}
```

- 직접적으로 에러를 발생시키지 않는 예외적인 상황이 발생할 수도 있다. 예외적인 상황에 적절하게 대응하지 않으면 에러로 이어질 수 있다.

```jsx
//button 요소가 존재하지 않으면 null을 반환한다.
const $button = document.querySelector('button'); // null

$button.classLIst.add('disabled'); //TypeError: Cannot read property 'classList' of null
```

- querySelector 메서드는 인수로 전달한 CSS 선택자 문자열로 DOM에서 요소 노드를 찾을 수 없는 경우 에러를 발생시키지 않고 null을 반환한다.
이때 if문 또는 단축 평가, 옵셔널 체이닝 연산자 ?.를 사용하지 않으면 에러로 이어질 가능성이 있다.

```jsx
//button 요소가 존재하지 않으면 null을 반환한다.
const $button = dcument.querySelector('button'); // null
$button?.classList.add('disabled');
```

- 에러나 예외적인 상황은 다양하기 때문에 아무런 조치없이 프로그램이 강제 종료된다면 원인을 파악하여 대응하기 어렵다.
- 언제나 에러나 예외적인 상황이 발생할 수 있다는 것을 전제하고 대응하는 코드를 작성하는 것이 중요하다.

# 47.2 try…catch…finally 문

- 일반적으로 에러 처리를 구현하는 방법은 크게 두 가지가 있다.
    - 예외적인 상황이 발생하면 반환하는 값(null 또는 -1)을 if문이나 단축 평가, 옵셔널 체이닝 연산자를 통해 확인해서 처리하는 방법
    - 에러 처리 코드를 미리 등록해두고 에러가 발생하면 에러 처리 코드로 점프하도록 하는 방법
        - try…catch…finally 문
- 두번째 방법을 `에러 처리`라고 한다.
- try…catch…finally 문은 3개의 코드 블록으로 구성된다.
    - finally는 생략 가능하다.
    - catch문도 생략 가능하지만 catch문이 없는 try문은 의미 없으므로 생략하지 않는다.
    
    ```jsx
    try{
    	//에러가 발생할 가능성이 있는 코드
    } catch (err) {
    	// 에러 발생 시 실행. try 코드 블록에서 발생한 에러 객체 실행.
    } finally {
    	//에러 발생과 상관 없이 반드시 한 번 실행
    }
    ```
    
    - err 변수는 try에서 에러가 발생하면 생성되고, catch코드 블록에서만 유효하다.
    - try…catch…finally를 사용하면 프로그램이 강제로 종료되지 않는다.

# 47.3 Error 객체

- Error 생성자 함수는 에러 객체를 생성한다. 에러를 상세히 설명하는 에러 메시지를 생성자 함수에 인수로 전달할 수 있다.
    
    ```jsx
    const error = new Error('invalid');
    ```
    
- 에러 객체는 message 프로퍼티와 stack 프로퍼티를 갖는다.
    - `message`: 인수로 전달한 에러 메시지
    - `stack`: 에러를 발생시킨 콜스택의 호출 정보를 나타내는 문자열. 디버깅 시 사용
- 자바스크립트는 Error 생성자 함수를 포함해 7개의 에러 객체를 생성할 수 있는 Error 생성자 함수를 제공한다. 이 에러 객체의 프로토타입은 모두 Error.prototype을 상속받는다.
    
    
    | 생성자 함수 | 인스턴스 |
    | --- | --- |
    | Error | 일반적 에러 객체 |
    | SyntaxError | 자바스크립트 문법에 맞지 않는 문을 해석할 때 발생. |
    | ReferenceError | 참조할 수 없는 식별자를 참조했을 때 발생. |
    | TypeError | 피연산자 또는 인수의 데이터 타입이 유효하지 않을 때 발생. |
    | RangeError |  숫자 값의 허용 범위를 벗어났을 때 발생. |
    | URIError | encodeURI, decodeURI 함수에 부적절한 인수를 전달했을 때 발생. |
    | EvalError | eval 함수에서 발생. |
    
    ```jsx
    1 @ 1; //SyntaxError
    foo(); // ReferenceError: foo is not defined
    null.foo; //TypeError: Cannot read property 'foo' of null
    new Array(-1) // RangeError: Invalid array length
    decodeURIComponent('%'); //URIError: URI malformed
    ```
    

# 47.4 throw문

- Error 생성자 함수로 에러 객체를 생성한다고 에러가 발생하는 것은 아니다.
- 에러를 발생시키려면 try 코드 블록에서 throw 문으로 에러 객체를 던져야 한다.
    
    ```jsx
    throw 표현식;
    ```
    
- throw 문의 표현식은 어떤 값이라도 상관 없지만, 일반적으로 에러 객체를 지정한다. 에러를 던지면 catch문의 에러 변수가 생성되고 던져진 에러 객체가 할당된다. 그리고 catch코드 블록이 실행되기 시작한다.
    
    ```jsx
    try {
    	throw new Error('something wrong');
    } catch(error){
    	console.log(error);
    }
    ```
    
- 외부에서 전달받은 콜백 함수를 n번만큼 반복 호출하는 repeat함수 구현 예시
    
    ```jsx
    const repeat = (n, f) =>{
    	if(typeof f !== 'function') throw new TypeError('f must be a function');
    
    	for(var i = 0 ; i < n ; i++ ){
    		f(i);
    	}
    };
    
    try {
    	repeat(2, 1);
    } catch(err) {
    	console.error(err); //TypeError: f must be a function
    }
    ```
    

# 47.5 에러의 전파

- 에러는 호출자 방향으로 전파된다. 즉, 콜 스택의 아래 방향으로 전파된다.
    
    ```jsx
    const foo = () => {
    	throw Error('foo에서 발생한 에러');
    }
    
    const bar = () => {
    	foo();
    }
    
    const baz = () => {
    	bar();
    }
    
    try{
    	baz();
    }catch(err){
    	console.error(err);
    }
    ```
    
    - 여기서 foo 함수가 throw한 에러는 호출자에게 전파되어 전역에서 캐치된다.
        
        (foo 실행 컨텍스트 →  bar 실행 컨텍스트  → baz 실행 컨텍스트 → 전역 실행 컨텍스트 )
        
    - throw된 에러를 캐치하지 않으면 호출자 방향으로 전파된다.
    - 에러를 캐치하여 적절히 대응하면 코드의 실행 흐름을 복구 할 수 있으나, 어디에서도 캐치하지 않으면 프로그램은 강제 종료된다.
    - ⭐ **주의할 점은 비동기 함수인 setTimeout이나 프로미스 후속 처리 메서드의 콜백 함수는 호출자가 없다는 것이다.**
    이들은 태스크 큐나 마이크로태스크 큐에 일시 저장되었다가 콜 스택이 빌 때 콜 스택으로 푸시되어 실행되는데, 스택의 가장 하부에 존재하게 된다. 따라서 에러를 전파할 호출자가 존재하지 않는다.